Workbook

Sheet Employee_Data
A1: Employee_ID | B1: First_Name | C1: Last_Name | D1: Email | E1: Department | F1: Job_Title | G1: City | H1: Join_Date | I1: Date_of_Birth | J1: Employment_Type | K1: Status | L1: Salary_Band | M1: Annual_Salary | N1: Bonus | O1: Sales_Target | P1: Sales_Achieved | Q1: Satisfaction_Score | R1: Absent_Days | S1: Performance_Rating | T1: Recruitment_Source | U1: Salary_Level | V1: Target_Status | W1: Attendance_Status | X1: Performance_Flag | Y1: Vlookup | Z1: Ifeffor Estimated Bonus | AA1: Final Pay | AB1: Return Minimum Salary Bonus | AC1: Return Maximum Salary Bonus | AD1: Return Band Bonus Rate | AE1: Eligibility
A2: EMP001 | B2: Aisha | C2: Okafor | D2: aisha.okafor@northstar-group.com | E2: Sales | F2: Sales Analyst | G2: Lagos | H2: 44292 | I2: 31457 | J2: Full-time | K2: Active | L2: Junior | M2: 283810 | N2: 26868 | O2: 97 | P2: 94 | Q2: 98 | R2: 11 | S2: Needs Improvement | T2: LinkedIn | U2: {=IF($M2:M101<=320000,"Junior",IF($M2:M101<=549000,"Mid_Level",IF($M2:M101>=550000,"Senior")))} -> Junior | V2: {=IF(O2:O101>=P2:P101,"Met Target","Below Target")} -> Met Target | W2: {=IF($R2:R101>7,"High Absence","Normal")} -> High Absence | X2: {=IF(S2:S101="Excellent","Review For Reward","Normal Review")} -> Normal Review | Y2: =VLOOKUP($L2,Lookup_Table!$A$1:$D$4,4,FALSE) -> 0.05 | Z2: =IFERROR(M2*Y2,0) -> 14190.5 | AA2: =SUM(M2,N2,Z2) -> 324868.5 | AB2: =VLOOKUP($L2,Lookup_Table!$A$2:$D$4,2,FALSE) -> 180000 | AC2: =VLOOKUP($L2,Lookup_Table!$A$2:$D$4,3,FALSE) -> 319999 | AD2: =VLOOKUP($L2,Lookup_Table!$A$2:$D$4,4) -> 0.05 | AE2: {=IF(AA2:AA2,"Correct Band","Check Band")} -> Correct Band
A3: EMP002 | B3: Daniel | C3: Mensah | D3: daniel.mensah@northstar-group.com | E3: Finance | F3: Financial Analyst | G3: Abuja | H3: 45564 | I3: 31568 | J3: Full-time | K3: On Leave | L3: Mid-Level | M3: 477397 | N3: 6956 | O3: 51 | P3: 36 | Q3: 90 | R3: 3 | S3: Needs Improvement | T3: Indeed | U3: Mid_Level | V3: Met Target | W3: Normal | X3: Normal Review | Y3: =VLOOKUP($L3,Lookup_Table!$A$1:$D$4,4,FALSE) -> 0.08 | Z3: =IFERROR(M3*Y3,0) -> 38191.76 | AA3: =SUM(M3,N3,Z3) -> 522544.76 | AB3: =VLOOKUP($L3,Lookup_Table!$A$2:$D$4,2,FALSE) -> 320000 | AC3: =VLOOKUP($L3,Lookup_Table!$A$2:$D$4,3,FALSE) -> 549999 | AD3: =VLOOKUP($L3,Lookup_Table!$A$2:$D$4,4) -> 0.08 | AE3: {=IF(AA3:AA3,"Correct Band","Check Band")} -> Correct Band
A4: EMP003 | B4: Grace | C4: Adeyemi | D4: grace.adeyemi@northstar-group.com | E4: Operations | F4: Operations Analyst | G4: Port Harcourt | H4: 45675 | I4: 40702 | J4: Contract | K4: Active | L4: Senior | M4: 728893 | N4: 72842 | O4: 67 | P4: 47 | Q4: 64 | R4: 3 | S4: Good | T4: LinkedIn | U4: Senior | V4: Met Target | W4: Normal | X4: Normal Review | Y4: =VLOOKUP($L4,Lookup_Table!$A$1:$D$4,4,FALSE) -> 0.12 | Z4: =IFERROR(M4*Y4,0) -> 87467.16 | AA4: =SUM(M4,N4,Z4) -> 889202.16 | AB4: =VLOOKUP($L4,Lookup_Table!$A$2:$D$4,2,FALSE) -> 550000 | AC4: =VLOOKUP($L4,Lookup_Table!$A$2:$D$4,3,FALSE) -> 999999 | AD4: =VLOOKUP($L4,Lookup_Table!$A$2:$D$4,4) -> 0.12 | AE4: {=IF(AA4:AA4,"Correct Band","Check Band")} -> Correct Band
A5: EMP004 | B5: Michael | C5: Bello | D5: michael.bello@northstar-group.com | E5: IT | F5: Systems Analyst | G5: Ibadan | H5: 45392 | I5: 32632 | J5: Full-time | K5: Active | L5: Junior | M5: 212156 | N5: 120435 | O5: 72 | P5: 74 | Q5: 89 | R5: 1 | S5: Average | T5: LinkedIn | U5: Junior | V5: Below Target | W5: Normal | X5: Normal Review | Y5: =VLOOKUP($L5,Lookup_Table!$A$1:$D$4,4,FALSE) -> 0.05 | Z5: =IFERROR(M5*Y5,0) -> 10607.8 | AA5: =SUM(M5,N5,Z5) -> 343198.8 | AB5: =VLOOKUP($L5,Lookup_Table!$A$2:$D$4,2,FALSE) -> 180000 | AC5: =VLOOKUP($L5,Lookup_Table!$A$2:$D$4,3,FALSE) -> 319999 | AD5: =VLOOKUP($L5,Lookup_Table!$A$2:$D$4,4) -> 0.05 | AE5: {=IF(AA5:AA5,"Correct Band","Check Band")} -> Correct Band
A6: EMP005 | B6: Chiamaka | C6: Eze | D6: chiamaka.eze@northstar-group.com | E6: HR | F6: HR Associate | G6: Kano | H6: 45036 | I6: 41347 | J6: Full-time | K6: Resigned | L6: Mid-Level | M6: 472357 | N6: 18233 | O6: 89 | P6: 92 | Q6: 57 | R6: 10 | S6: Good | T6: Referral | U6: Mid_Level | V6: Below Target | W6: High Absence | X6: Normal Review | Y6: =VLOOKUP($L6,Lookup_Table!$A$1:$D$4,4,FALSE) -> 0.08 | Z6: =IFERROR(M6*Y6,0) -> 37788.56 | AA6: =SUM(M6,N6,Z6) -> 528378.56 | AB6: =VLOOKUP($L6,Lookup_Table!$A$2:$D$4,2,FALSE) -> 320000 | AC6: =VLOOKUP($L6,Lookup_Table!$A$2:$D$4,3,FALSE) -> 549999 | AD6: =VLOOKUP($L6,Lookup_Table!$A$2:$D$4,4) -> 0.08 | AE6: {=IF(AA6:AA6,"Correct Band","Check Band")} -> Correct Band
A7: EMP006 | B7: David | C7: Okoro | D7: david.okoro@northstar-group.com | E7: Marketing | F7: Marketing Coordinator | G7: Owerri | H7: 44789 | I7: 32702 | J7: Full-time | K7: Active | L7: Senior | M7: 710458 | N7: 97040 | O7: 74 | P7: 71 | Q7: 77 | R7: 3 | S7: Good | T7: LinkedIn | U7: Senior | V7: Met Target | W7: Normal | X7: Normal Review | Y7: =VLOOKUP($L7,Lookup_Table!$A$1:$D$4,4,FALSE) -> 0.12 | Z7: =IFERROR(M7*Y7,0) -> 85254.96 | AA7: =SUM(M7,N7,Z7) -> 892752.96 | AB7: =VLOOKUP($L7,Lookup_Table!$A$2:$D$4,2,FALSE) -> 550000 | AC7: =VLOOKUP($L7,Lookup_Table!$A$2:$D$4,3,FALSE) -> 999999 | AD7: =VLOOKUP($L7,Lookup_Table!$A$2:$D$4,4) -> 0.12 | AE7: {=IF(AA7:AA7,"Correct Band","Check Band")} -> Correct Band
A8: EMP007 | B8: Sarah | C8: Ibrahim | D8: sarah.ibrahim@northstar-group.com | E8: Customer Success | F8: Customer Success Analyst | G8: Enugu | H8: 44536 | I8: 39799 | J8: Contract | K8: Active | L8: Junior | M8: 279840 | N8: 70765 | O8: 96 | P8: 91 | Q8: 95 | R8: 11 | S8: Needs Improvement | T8: Company Website | U8: Junior | V8: Met Target | W8: High Absence | X8: Normal Review | Y8: =VLOOKUP($L8,Lookup_Table!$A$1:$D$4,4,FALSE) -> 0.05 | Z8: =IFERROR(M8*Y8,0) -> 13992 | AA8: =SUM(M8,N8,Z8) -> 364597 | AB8: =VLOOKUP($L8,Lookup_Table!$A$2:$D$4,2,FALSE) -> 180000 | AC8: =VLOOKUP($L8,Lookup_Table!$A$2:$D$4,3,FALSE) -> 319999 | AD8: =VLOOKUP($L8,Lookup_Table!$A$2:$D$4,4) -> 0.05 | AE8: {=IF(AA8:AA8,"Correct Band","Check Band")} -> Correct Band
A9: EMP008 | B9: James | C9: Adebayo | D9: james.adebayo@northstar-group.com | E9: Sales | F9: Account Executive | G9: Lagos | H9: 45164 | I9: 31964 | J9: Contract | K9: Active | L9: Mid-Level | M9: 489733 | N9: 17350 | O9: 64 | P9: 46 | Q9: 68 | R9: 9 | S9: Good | T9: Company Website | U9: Mid_Level | V9: Met Target | W9: High Absence | X9: Normal Review | Y9: =VLOOKUP($L9,Lookup_Table!$A$1:$D$4,4,FALSE) -> 0.08 | Z9: =IFERROR(M9*Y9,0) -> 39178.64 | AA9: =SUM(M9,N9,Z9) -> 546261.64 | AB9: =VLOOKUP($L9,Lookup_Table!$A$2:$D$4,2,FALSE) -> 320000 | AC9: =VLOOKUP($L9,Lookup_Table!$A$2:$D$4,3,FALSE) -> 549999 | AD9: =VLOOKUP($L9,Lookup_Table!$A$2:$D$4,4) -> 0.08 | AE9: {=IF(AA9:AA9,"Correct Band","Check Band")} -> Correct Band
A10: EMP009 | B10: Blessing | C10: Nwosu | D10: blessing.nwosu@northstar-group.com | E10: Finance | F10: Financial Analyst | G10: Abuja | H10: 45880 | I10: 37530 | J10: Full-time | K10: Active | L10: Senior | M10: 785909 | N10: 64651 | O10: 91 | P10: 100 | Q10: 90 | R10: 8 | S10: Good | T10: Recruitment Agency | U10: Senior | V10: Below Target | W10: High Absence | X10: Normal Review | Y10: =VLOOKUP($L10,Lookup_Table!$A$1:$D$4,4,FALSE) -> 0.12 | Z10: =IFERROR(M10*Y10,0) -> 94309.08 | AA10: =SUM(M10,N10,Z10) -> 944869.08 | AB10: =VLOOKUP($L10,Lookup_Table!$A$2:$D$4,2,FALSE) -> 550000 | AC10: =VLOOKUP($L10,Lookup_Table!$A$2:$D$4,3,FALSE) -> 999999 | AD10: =VLOOKUP($L10,Lookup_Table!$A$2:$D$4,4) -> 0.12 | AE10: {=IF(AA10:AA10,"Correct Band","Check Band")} -> Correct Band
A11: EMP010 | B11: Victor | C11: Umeh | D11: victor.umeh@northstar-group.com | E11: Operations | F11: Operations Analyst | G11: Port Harcourt | H11: 46226 | I11: 37591 | J11: Contract | K11: Active | L11: Junior | M11: 256155 | N11: 12351 | O11: 73 | P11: 67 | Q11: 62 | R11: 2 | S11: Good | T11: Indeed | U11: Junior | V11: Met Target | W11: Normal | X11: Normal Review | Y11: =VLOOKUP($L11,Lookup_Table!$A$1:$D$4,4,FALSE) -> 0.05 | Z11: =IFERROR(M11*Y11,0) -> 12807.75 | AA11: =SUM(M11,N11,Z11) -> 281313.75 | AB11: =VLOOKUP($L11,Lookup_Table!$A$2:$D$4,2,FALSE) -> 180000 | AC11: =VLOOKUP($L11,Lookup_Table!$A$2:$D$4,3,FALSE) -> 319999 | AD11: =VLOOKUP($L11,Lookup_Table!$A$2:$D$4,4) -> 0.05 | AE11: {=IF(AA11:AA11,"Correct Band","Check Band")} -> Correct Band
A12: EMP011 | B12: John | C12: Smith | D12: john.smith@northstar-group.com | E12: IT | F12: IT Support Specialist | G12: Ibadan | H12: 44096 | I12: 37352 | J12: Full-time | K12: On Leave | L12: Mid-Level | M12: 478172 | N12: 3009 | O12: 74 | P12: 92 | Q12: 98 | R12: 11 | S12: Excellent | T12: Recruitment Agency | U12: Mid_Level | V12: Below Target | W12: High Absence | X12: Review For Reward | Y12: =VLOOKUP($L12,Lookup_Table!$A$1:$D$4,4,FALSE) -> 0.08 | Z12: =IFERROR(M12*Y12,0) -> 38253.76 | AA12: =SUM(M12,N12,Z12) -> 519434.76 | AB12: =VLOOKUP($L12,Lookup_Table!$A$2:$D$4,2,FALSE) -> 320000 | AC12: =VLOOKUP($L12,Lookup_Table!$A$2:$D$4,3,FALSE) -> 549999 | AD12: =VLOOKUP($L12,Lookup_Table!$A$2:$D$4,4) -> 0.08 | AE12: {=IF(AA12:AA12,"Correct Band","Check Band")} -> Correct Band
A13: EMP012 | B13: Mary | C13: Williams | D13: mary.williams@northstar-group.com | E13: HR | F13: Recruitment Specialist | G13: Kano | H13: 44928 | I13: 41549 | J13: Contract | K13: Active | L13: Senior | M13: 798419 | N13: 118940 | O13: 71 | P13: 58 | Q13: 55 | R13: 11 | S13: Good | T13: Recruitment Agency | U13: Senior | V13: Met Target | W13: High Absence | X13: Normal Review | Y13: =VLOOKUP($L13,Lookup_Table!$A$1:$D$4,4,FALSE) -> 0.12 | Z13: =IFERROR(M13*Y13,0) -> 95810.28 | AA13: =SUM(M13,N13,Z13) -> 1013169.3 | AB13: =VLOOKUP($L13,Lookup_Table!$A$2:$D$4,2,FALSE) -> 550000 | AC13: =VLOOKUP($L13,Lookup_Table!$A$2:$D$4,3,FALSE) -> 999999 | AD13: =VLOOKUP($L13,Lookup_Table!$A$2:$D$4,4) -> 0.12 | AE13: {=IF(AA13:AA13,"Correct Band","Check Band")} -> Correct Band
A14: EMP013 | B14: Peter | C14: Johnson | D14: peter.johnson@northstar-group.com | E14: Marketing | F14: Marketing Coordinator | G14: Owerri | H14: 44567 | I14: 39365 | J14: Full-time | K14: Active | L14: Junior | M14: 299871 | N14: 98019 | O14: 56 | P14: 76 | Q14: 65 | R14: 8 | S14: Needs Improvement | T14: LinkedIn | U14: Junior | V14: Below Target | W14: High Absence | X14: Normal Review | Y14: =VLOOKUP($L14,Lookup_Table!$A$1:$D$4,4,FALSE) -> 0.05 | Z14: =IFERROR(M14*Y14,0) -> 14993.55 | AA14: =SUM(M14,N14,Z14) -> 412883.55 | AB14: =VLOOKUP($L14,Lookup_Table!$A$2:$D$4,2,FALSE) -> 180000 | AC14: =VLOOKUP($L14,Lookup_Table!$A$2:$D$4,3,FALSE) -> 319999 | AD14: =VLOOKUP($L14,Lookup_Table!$A$2:$D$4,4) -> 0.05 | AE14: {=IF(AA14:AA14,"Correct Band","Check Band")} -> Correct Band
... A101: EMP100 | B101: Victor | C101: Mensah | D101: victor.mensah@northstar-group.com | E101: Finance | F101: Finance Associate | G101: Abuja | H101: 46135 | I101: 36422 | J101: Full-time | K101: Resigned | L101: Junior | M101: 203280 | N101: 121704 | O101: 89 | P101: 83 | Q101: 74 | R101: 10 | S101: Average | T101: LinkedIn | U101: Junior | V101: Met Target | W101: High Absence | X101: Normal Review | Y101: =VLOOKUP($L101,Lookup_Table!$A$1:$D$4,4,FALSE) -> 0.05 | Z101: =IFERROR(M101*Y101,0) -> 10164 | AA101: =SUM(M101,N101,Z101) -> 335148 | AB101: =VLOOKUP($L101,Lookup_Table!$A$2:$D$4,2,FALSE) -> 180000 | AC101: =VLOOKUP($L101,Lookup_Table!$A$2:$D$4,3,FALSE) -> 319999 | AD101: =VLOOKUP($L101,Lookup_Table!$A$2:$D$4,4) -> 0.05 | AE101: {=IF(AA101:AA101,"Correct Band","Check Band")} -> Correct Band
I105: DEP | P105: JOINING YEAR | Q105: NUMBER OF EMPLOYEE
B106: =_xlfn.CONCAT(B2," ",C2) -> Aisha Okafor | C106: =LOWER(D2) -> aisha.okafor@northstar-group.com | D106: =_xlfn.CONCAT(A2," ",B106) -> EMP001 Aisha Okafor | E106: =PROPER(B106) -> Aisha Okafor | F106: =LEFT(A2,3) -> EMP | G106: =RIGHT(A2,3) -> 001 | H106: =LEN(E106) -> 13 | J106: =YEAR(H2) -> 2021 | K106: =MONTH(H2) -> 4 | L106: =TEXT(H2,"MMMM") -> April | M106: =TEXT(H2,"DDDD") -> Tuesday | N106: =DATEDIF(I2,TODAY(),"Y") -> 40 | O106: =DATEDIF(H2,TODAY(),"Y") -> 5 | P106: 21/052020 | Q106: =COUNTIF(H2:H101,P106) -> 0
B107: =_xlfn.CONCAT(B3," ",C3) -> Daniel Mensah | C107: =LOWER(D3) -> daniel.mensah@northstar-group.com | D107: =_xlfn.CONCAT(A3," ",B107) -> EMP002 Daniel Mensah | E107: =PROPER(B107) -> Daniel Mensah | F107: =LEFT(A3,3) -> EMP | G107: =RIGHT(A3,3) -> 002 | H107: =LEN(E107) -> 14 | J107: =YEAR(H3) -> 2024 | K107: =MONTH(H3) -> 9 | L107: =TEXT(H3,"MMMM") -> September | M107: =TEXT(H3,"DDDD") -> Sunday | N107: =DATEDIF(I3,TODAY(),"Y") -> 40 | O107: =DATEDIF(H3,TODAY(),"Y") -> 1 | P107: 2021
B108: =_xlfn.CONCAT(B4," ",C4) -> Grace Adeyemi | C108: =LOWER(D4) -> grace.adeyemi@northstar-group.com | D108: =_xlfn.CONCAT(A4," ",B108) -> EMP003 Grace Adeyemi | E108: =PROPER(B108) -> Grace Adeyemi | F108: =LEFT(A4,3) -> EMP | G108: =RIGHT(A4,3) -> 003 | H108: =LEN(E108) -> 14 | J108: =YEAR(H4) -> 2025 | K108: =MONTH(H4) -> 1 | L108: =TEXT(H4,"MMMM") -> January | M108: =TEXT(H4,"DDDD") -> Saturday | N108: =DATEDIF(I4,TODAY(),"Y") -> 15 | O108: =DATEDIF(H4,TODAY(),"Y") -> 1 | P108: 2022
B109: =_xlfn.CONCAT(B5," ",C5) -> Michael Bello | C109: =LOWER(D5) -> michael.bello@northstar-group.com | D109: =_xlfn.CONCAT(A5," ",B109) -> EMP004 Michael Bello | E109: =PROPER(B109) -> Michael Bello | F109: =LEFT(A5,3) -> EMP | G109: =RIGHT(A5,3) -> 004 | H109: =LEN(E109) -> 14 | J109: =YEAR(H5) -> 2024 | K109: =MONTH(H5) -> 4 | L109: =TEXT(H5,"MMMM") -> April | M109: =TEXT(H5,"DDDD") -> Wednesday | N109: =DATEDIF(I5,TODAY(),"Y") -> 37 | O109: =DATEDIF(H5,TODAY(),"Y") -> 2 | P109: 2023
B110: =_xlfn.CONCAT(B6," ",C6) -> Chiamaka Eze | C110: =LOWER(D6) -> chiamaka.eze@northstar-group.com | D110: =_xlfn.CONCAT(A6," ",B110) -> EMP005 Chiamaka Eze | E110: =PROPER(B110) -> Chiamaka Eze | F110: =LEFT(A6,3) -> EMP | G110: =RIGHT(A6,3) -> 005 | H110: =LEN(E110) -> 13 | J110: =YEAR(H6) -> 2023 | K110: =MONTH(H6) -> 4 | L110: =TEXT(H6,"MMMM") -> April | M110: =TEXT(H6,"DDDD") -> Thursday | N110: =DATEDIF(I6,TODAY(),"Y") -> 13 | O110: =DATEDIF(H6,TODAY(),"Y") -> 3 | P110: 2024
B111: =_xlfn.CONCAT(B7," ",C7) -> David Okoro | C111: =LOWER(D7) -> david.okoro@northstar-group.com | D111: =_xlfn.CONCAT(A7," ",B111) -> EMP006 David Okoro | E111: =PROPER(B111) -> David Okoro | F111: =LEFT(A7,3) -> EMP | G111: =RIGHT(A7,3) -> 006 | H111: =LEN(E111) -> 12 | J111: =YEAR(H7) -> 2022 | K111: =MONTH(H7) -> 8 | L111: =TEXT(H7,"MMMM") -> August | M111: =TEXT(H7,"DDDD") -> Tuesday | N111: =DATEDIF(I7,TODAY(),"Y") -> 37 | O111: =DATEDIF(H7,TODAY(),"Y") -> 4 | P111: 2025
B112: =_xlfn.CONCAT(B8," ",C8) -> Sarah Ibrahim | C112: =LOWER(D8) -> sarah.ibrahim@northstar-group.com | D112: =_xlfn.CONCAT(A8," ",B112) -> EMP007 Sarah Ibrahim | E112: =PROPER(B112) -> Sarah Ibrahim | F112: =LEFT(A8,3) -> EMP | G112: =RIGHT(A8,3) -> 007 | H112: =LEN(E112) -> 14 | J112: =YEAR(H8) -> 2021 | K112: =MONTH(H8) -> 12 | L112: =TEXT(H8,"MMMM") -> December | M112: =TEXT(H8,"DDDD") -> Monday | N112: =DATEDIF(I8,TODAY(),"Y") -> 17 | O112: =DATEDIF(H8,TODAY(),"Y") -> 4 | P112: 2026
B113: =_xlfn.CONCAT(B9," ",C9) -> James Adebayo | C113: =LOWER(D9) -> james.adebayo@northstar-group.com | D113: =_xlfn.CONCAT(A9," ",B113) -> EMP008 James Adebayo | E113: =PROPER(B113) -> James Adebayo | F113: =LEFT(A9,3) -> EMP | G113: =RIGHT(A9,3) -> 008 | H113: =LEN(E113) -> 14 | J113: =YEAR(H9) -> 2023 | K113: =MONTH(H9) -> 8 | L113: =TEXT(H9,"MMMM") -> August | M113: =TEXT(H9,"DDDD") -> Saturday | N113: =DATEDIF(I9,TODAY(),"Y") -> 39 | O113: =DATEDIF(H9,TODAY(),"Y") -> 3
B114: =_xlfn.CONCAT(B10," ",C10) -> Blessing Nwosu | C114: =LOWER(D10) -> blessing.nwosu@northstar-group.com | D114: =_xlfn.CONCAT(A10," ",B114) -> EMP009 Blessing Nwosu | E114: =PROPER(B114) -> Blessing Nwosu | F114: =LEFT(A10,3) -> EMP | G114: =RIGHT(A10,3) -> 009 | H114: =LEN(E114) -> 15 | J114: =YEAR(H10) -> 2025 | K114: =MONTH(H10) -> 8 | L114: =TEXT(H10,"MMMM") -> August | M114: =TEXT(H10,"DDDD") -> Monday | N114: =DATEDIF(I10,TODAY(),"Y") -> 23 | O114: =DATEDIF(H10,TODAY(),"Y") -> 1
B115: =_xlfn.CONCAT(B11," ",C11) -> Victor Umeh | C115: =LOWER(D11) -> victor.umeh@northstar-group.com | D115: =_xlfn.CONCAT(A11," ",B115) -> EMP010 Victor Umeh | E115: =PROPER(B115) -> Victor Umeh | F115: =LEFT(A11,3) -> EMP | G115: =RIGHT(A11,3) -> 010 | H115: =LEN(E115) -> 12 | J115: =YEAR(H11) -> 2026 | K115: =MONTH(H11) -> 7 | L115: =TEXT(H11,"MMMM") -> July | M115: =TEXT(H11,"DDDD") -> Thursday | N115: =DATEDIF(I11,TODAY(),"Y") -> 23 | O115: =DATEDIF(H11,TODAY(),"Y") -> 0
B116: =_xlfn.CONCAT(B12," ",C12) -> John Smith | C116: =LOWER(D12) -> john.smith@northstar-group.com | D116: =_xlfn.CONCAT(A12," ",B116) -> EMP011 John Smith | E116: =PROPER(B116) -> John Smith | F116: =LEFT(A12,3) -> EMP | G116: =RIGHT(A12,3) -> 011 | H116: =LEN(E116) -> 11 | J116: =YEAR(H12) -> 2020 | K116: =MONTH(H12) -> 9 | L116: =TEXT(H12,"MMMM") -> September | M116: =TEXT(H12,"DDDD") -> Tuesday | N116: =DATEDIF(I12,TODAY(),"Y") -> 24 | O116: =DATEDIF(H12,TODAY(),"Y") -> 6
B117: =_xlfn.CONCAT(B13," ",C13) -> Mary Williams | C117: =LOWER(D13) -> mary.williams@northstar-group.com | D117: =_xlfn.CONCAT(A13," ",B117) -> EMP012 Mary Williams | E117: =PROPER(B117) -> Mary Williams | F117: =LEFT(A13,3) -> EMP | G117: =RIGHT(A13,3) -> 012 | H117: =LEN(E117) -> 14 | J117: =YEAR(H13) -> 2023 | K117: =MONTH(H13) -> 1 | L117: =TEXT(H13,"MMMM") -> January | M117: =TEXT(H13,"DDDD") -> Monday | N117: =DATEDIF(I13,TODAY(),"Y") -> 12 | O117: =DATEDIF(H13,TODAY(),"Y") -> 3
B118: =_xlfn.CONCAT(B14," ",C14) -> Peter Johnson | C118: =LOWER(D14) -> peter.johnson@northstar-group.com | D118: =_xlfn.CONCAT(A14," ",B118) -> EMP013 Peter Johnson | E118: =PROPER(B118) -> Peter Johnson | F118: =LEFT(A14,3) -> EMP | G118: =RIGHT(A14,3) -> 013 | H118: =LEN(E118) -> 14 | J118: =YEAR(H14) -> 2022 | K118: =MONTH(H14) -> 1 | L118: =TEXT(H14,"MMMM") -> January | M118: =TEXT(H14,"DDDD") -> Thursday | N118: =DATEDIF(I14,TODAY(),"Y") -> 18 | O118: =DATEDIF(H14,TODAY(),"Y") -> 4
B119: =_xlfn.CONCAT(B15," ",C15) -> Esther Brown | C119: =LOWER(D15) -> esther.brown@northstar-group.com | D119: =_xlfn.CONCAT(A15," ",B119) -> EMP014 Esther Brown | E119: =PROPER(B119) -> Esther Brown | F119: =LEFT(A15,3) -> EMP | G119: =RIGHT(A15,3) -> 014 | H119: =LEN(E119) -> 13 | J119: =YEAR(H15) -> 2023 | K119: =MONTH(H15) -> 8 | L119: =TEXT(H15,"MMMM") -> August | M119: =TEXT(H15,"DDDD") -> Friday | N119: =DATEDIF(I15,TODAY(),"Y") -> 19 | O119: =DATEDIF(H15,TODAY(),"Y") -> 3
B120: =_xlfn.CONCAT(B16," ",C16) -> Ifeoma Okafor | C120: =LOWER(D16) -> ifeoma.okafor@northstar-group.com | D120: =_xlfn.CONCAT(A16," ",B120) -> EMP015 Ifeoma Okafor | E120: =PROPER(B120) -> Ifeoma Okafor | F120: =LEFT(A16,3) -> EMP | G120: =RIGHT(A16,3) -> 015 | H120: =LEN(E120) -> 14 | J120: =YEAR(H16) -> 2025 | K120: =MONTH(H16) -> 6 | L120: =TEXT(H16,"MMMM") -> June | M120: =TEXT(H16,"DDDD") -> Wednesday | N120: =DATEDIF(I16,TODAY(),"Y") -> 38 | O120: =DATEDIF(H16,TODAY(),"Y") -> 1
B121: =_xlfn.CONCAT(B17," ",C17) -> Samuel Mensah | C121: =LOWER(D17) -> samuel.mensah@northstar-group.com | D121: =_xlfn.CONCAT(A17," ",B121) -> EMP016 Samuel Mensah | E121: =PROPER(B121) -> Samuel Mensah | F121: =LEFT(A17,3) -> EMP | G121: =RIGHT(A17,3) -> 016 | H121: =LEN(E121) -> 14 | J121: =YEAR(H17) -> 2024 | K121: =MONTH(H17) -> 10 | L121: =TEXT(H17,"MMMM") -> October | M121: =TEXT(H17,"DDDD") -> Friday | N121: =DATEDIF(I17,TODAY(),"Y") -> 32 | O121: =DATEDIF(H17,TODAY(),"Y") -> 1
B122: =_xlfn.CONCAT(B18," ",C18) -> Ruth Adeyemi | C122: =LOWER(D18) -> ruth.adeyemi@northstar-group.com | D122: =_xlfn.CONCAT(A18," ",B122) -> EMP017 Ruth Adeyemi | E122: =PROPER(B122) -> Ruth Adeyemi | F122: =LEFT(A18,3) -> EMP | G122: =RIGHT(A18,3) -> 017 | H122: =LEN(E122) -> 13 | J122: =YEAR(H18) -> 2022 | K122: =MONTH(H18) -> 7 | L122: =TEXT(H18,"MMMM") -> July | M122: =TEXT(H18,"DDDD") -> Thursday | N122: =DATEDIF(I18,TODAY(),"Y") -> 38 | O122: =DATEDIF(H18,TODAY(),"Y") -> 4
B123: =_xlfn.CONCAT(B19," ",C19) -> Emeka Bello | C123: =LOWER(D19) -> emeka.bello@northstar-group.com | D123: =_xlfn.CONCAT(A19," ",B123) -> EMP018 Emeka Bello | E123: =PROPER(B123) -> Emeka Bello | F123: =LEFT(A19,3) -> EMP | G123: =RIGHT(A19,3) -> 018 | H123: =LEN(E123) -> 12 | J123: =YEAR(H19) -> 2020 | K123: =MONTH(H19) -> 5 | L123: =TEXT(H19,"MMMM") -> May | M123: =TEXT(H19,"DDDD") -> Wednesday | N123: =DATEDIF(I19,TODAY(),"Y") -> 26 | O123: =DATEDIF(H19,TODAY(),"Y") -> 6
B124: =_xlfn.CONCAT(B20," ",C20) -> Linda Eze | C124: =LOWER(D20) -> linda.eze@northstar-group.com | D124: =_xlfn.CONCAT(A20," ",B124) -> EMP019 Linda Eze | E124: =PROPER(B124) -> Linda Eze | F124: =LEFT(A20,3) -> EMP | G124: =RIGHT(A20,3) -> 019 | H124: =LEN(E124) -> 10 | J124: =YEAR(H20) -> 2025 | K124: =MONTH(H20) -> 4 | L124: =TEXT(H20,"MMMM") -> April | M124: =TEXT(H20,"DDDD") -> Friday | N124: =DATEDIF(I20,TODAY(),"Y") -> 30 | O124: =DATEDIF(H20,TODAY(),"Y") -> 1
... B205: =_xlfn.CONCAT(B101," ",C101) -> Victor Mensah | C205: =LOWER(D101) -> victor.mensah@northstar-group.com | D205: =_xlfn.CONCAT(A101," ",B205) -> EMP100 Victor Mensah | E205: =PROPER(B205) -> Victor Mensah | F205: =LEFT(A101,3) -> EMP | G205: =RIGHT(A101,3) -> 100 | H205: =LEN(E205) -> 14 | J205: =YEAR(H101) -> 2026 | K205: =MONTH(H101) -> 4 | L205: =TEXT(H101,"MMMM") -> April | M205: =TEXT(H101,"DDDD") -> Thursday | N205: =DATEDIF(I101,TODAY(),"Y") -> 27 | O205: =DATEDIF(H101,TODAY(),"Y") -> 0
A209: Count Active employees in each department. | B209: =COUNTIF(K:K,"active") -> 74
A211: Count employees in each city | C211: CITY | D211: Number Of Employment | F211: Department | G211: Number Of Employment | I211: Department | J211: Bonus By Department | L211: Department | M211: AVG Satisfaction Score By Dep
A212: Calculate total Annual_Salary by department. | C212: Lagos | D212: =COUNTIF(G2:G101,C212) -> 15 | F212: Sales | G212: =SUMIF(E2:E101,F212,M2:M101) -> 7272395 | I212: Sales | J212: =SUMIF(E2:E101,I212,N2:N101) -> 1226862 | L212: Sales | M212: =SUMIF(E2:E101,L212,Q2:Q101) -> 1165
A213: Calculate total Bonus by department. | C213: Abuja | D213: =COUNTIF(G3:G102,C213) -> 15 | F213: Finance | G213: =SUMIF(E3:E102,F213,M3:M102) -> 7349960 | I213: Finance | J213: =SUMIF(E3:E102,I213,N3:N102) -> 1067667 | L213: Finance | M213: =SUMIF(E3:E102,L213,Q3:Q102) -> 1155
...

Sheet Sheet1
A1: Which department has the highest total salary cost? | B1: Finance Department | C1: =MAX(Employee_Data!G212:G218) -> 7349960
A2: Which city has the most employees? | B2: Lagos & Abuja | C2: =MAX(Employee_Data!D212:D218) -> 15 | E2: Employee Count by Department and Status
A3: Which department has the highest average satisfaction? | B3: Operations DEP | C3: =MAX(Employee_Data!M212:M218) -> 1178 | E3: Row Labels | F3: Count of Employee_ID | K3: Average Satisfaction_Score by Department. | N3: Total Bonus by City.
A4: How many employees are below target? | C4: =COUNTIF(_xlfn.ANCHORARRAY(Employee_Data!V2),"Below Target") -> 54 | E4: Customer Success | F4: 14 | H4: Sort the salary summary highest to lowest. | K4: Row Labels | L4: Sum of Satisfaction_Score | N4: Row Labels | O4: Sum of Bonus
A5: How many employees have high absence? | C5: =COUNTIF(Employee_Data!W:W,"High Absence") -> 40 | E5: Active | F5: 14 | H5: Row Labels | I5: Sum of Annual_Salary | K5: Customer Success | L5: 1069 | N5: Abuja | O5: 1067667
A6: What is the highest salary? | C6: =MAX(Employee_Data!M2:M101) -> 798419 | E6: Finance | F6: 15 | H6: EMP012 | I6: 798419 | K6: Finance | L6: 1155 | N6: Enugu | O6: 1091461
A7: What is the lowest salary? | C7: =MIN(Employee_Data!M2:M101) -> 201061 | E7: Active | F7: 12 | H7: EMP015 | I7: 795932 | K7: HR | L7: 1079 | N7: Ibadan | O7: 714451
A8: What is the average salary? | C8: =AVERAGE(Employee_Data!M2:M101) -> 483421.05 | E8: On Leave | F8: 1 | H8: EMP072 | I8: 792662 | K8: IT | L8: 1178 | N8: Kano | O8: 1017120
A9: What is total payroll (salary + bonus)? | C9: =SUM(Employee_Data!M2:M101,N2:N101) -> 48342182 | E9: Resigned | F9: 2 | H9: EMP027 | I9: 787782 | K9: Marketing | L9: 1004 | N9: Lagos | O9: 1226862
A10: Which employee has the highest Sales_Achieved? | B10: EMP099 Blessing Okafor | C10: =MAX(Employee_Data!P2:P101) -> 120 | E10: HR | F10: 14 | H10: EMP009 | I10: 785909 | K10: Operations | L10: 1017 | N10: Owerri | O10: 1400898
E11: Active | F11: 9 | H11: EMP075 | I11: 779129 | K11: Sales | L11: 1165 | N11: Port Harcourt | O11: 1174206
E12: On Leave | F12: 2 | H12: EMP057 | I12: 777607 | K12: Grand Total | L12: 7667 | N12: Grand Total | O12: 7692665
E13: Resigned | F13: 3 | H13: EMP033 | I13: 776350
E14: IT | F14: 14 | H14: EMP039 | I14: 768146
A15: Total Annual_Salary by Department | E15: Active | F15: 10 | H15: EMP051 | I15: 763993
A16: Row Labels | B16: Sum of Annual_Salary | E16: On Leave | F16: 1 | H16: EMP093 | I16: 763335
A17: Customer Success | B17: 6634937 | E17: Resigned | F17: 3 | H17: EMP087 | I17: 761537 | K17: Conditional formatting: salaries above 600,000.
A18: Finance | B18: 7349960 | E18: Marketing | F18: 14 | H18: EMP099 | I18: 759609 | K18: Row Labels | L18: Sum of Annual_Salary | N18: Conditional formatting: Absent_Days above 7.
A19: HR | B19: 7142603 | E19: Active | F19: 10 | H19: EMP096 | I19: 757779 | K19: EMP003 | L19: 728893 | N19: Row Labels | O19: Sum of Absent_Days
A20: IT | B20: 6361094 | E20: On Leave | F20: 3 | H20: EMP042 | I20: 756346 | K20: EMP006 | L20: 710458 | N20: 2 | O20: 8
A21: Marketing | B21: 6869489 | E21: Resigned | F21: 1 | H21: EMP090 | I21: 754008 | K21: EMP009 | L21: 785909 | N21: 3 | O21: 39
A22: Operations | B22: 6711627 | E22: Operations | F22: 14 | H22: EMP081 | I22: 753476 | K22: EMP012 | L22: 798419 | N22: 4 | O22: 32
A23: Sales | B23: 7272395 | E23: Active | F23: 10 | H23: EMP084 | I23: 745236 | K23: EMP015 | L23: 795932 | N23: 5 | O23: 30
A24: Grand Total | B24: 48342105 | E24: On Leave | F24: 1 | H24: EMP078 | I24: 741224 | K24: EMP018 | L24: 708834 | N24: 6 | O24: 30
E25: Resigned | F25: 3 | H25: EMP036 | I25: 740001 | K25: EMP021 | L25: 725112 | N25: 7 | O25: 63
E26: Sales | F26: 15 | H26: EMP066 | I26: 739618 | K26: EMP024 | L26: 724890 | N26: 8 | O26: 80
E27: Active | F27: 9 | H27: EMP063 | I27: 738566 | K27: EMP027 | L27: 787782 | N27: 9 | O27: 36
E28: On Leave | F28: 1 | H28: EMP030 | I28: 734664 | K28: EMP030 | L28: 734664 | N28: 10 | O28: 110
E29: Resigned | F29: 5 | H29: EMP003 | I29: 728893 | K29: EMP033 | L29: 776350 | N29: 11 | O29: 88
E30: Grand Total | F30: 100 | H30: EMP021 | I30: 725112 | K30: EMP036 | L30: 740001 | N30: 12 | O30: 84
H31: EMP024 | I31: 724890 | K31: EMP039 | L31: 768146 | N31: Grand Total | O31: 600
H32: EMP045 | I32: 719342 | K32: EMP042 | L32: 756346
H33: EMP069 | I33: 715525 | K33: EMP045 | L33: 719342
E34: Count By Employment Type. | H34: EMP060 | I34: 711359 | K34: EMP048 | L34: 710155
E35: Row Labels | F35: Count of Employee_ID | H35: EMP006 | I35: 710458 | K35: EMP051 | L35: 763993
E36: Contract | F36: 33 | H36: EMP048 | I36: 710155 | K36: EMP054 | L36: 702540
E37: Full-time | F37: 67 | H37: EMP018 | I37: 708834 | K37: EMP057 | L37: 777607
E38: Grand Total | F38: 100 | H38: EMP054 | I38: 702540 | K38: EMP060 | L38: 711359
H39: EMP065 | I39: 499901 | K39: EMP063 | L39: 738566
H40: EMP098 | I40: 498848 | K40: EMP066 | L40: 739618
...

Sheet Lookup_Table
A1: Salary_Band | B1: Minimum_Salary | C1: Maximum_Salary | D1: Band_Bonus_Rate
A2: Junior | B2: 180000 | C2: 319999 | D2: 0.05
A3: Mid-Level | B3: 320000 | C3: 549999 | D3: 0.08
A4: Senior | B4: 550000 | C4: 999999 | D4: 0.12
